[Fri Feb 07 17:49:55.669317 2020] [wsgi:error] [pid 15212] [remote 192.168.1.22:35666] mod_wsgi (pid=15212): Target WSGI script '/home/pi/maison/web_app/site_maison.wsgi' cannot be loaded as Python module.
[Fri Feb 07 17:49:55.669724 2020] [wsgi:error] [pid 15212] [remote 192.168.1.22:35666] mod_wsgi (pid=15212): Exception occurred processing WSGI script '/home/pi/maison/web_app/site_maison.wsgi'.
[Fri Feb 07 17:49:55.717208 2020] [wsgi:error] [pid 15212] [remote 192.168.1.22:35666] Traceback (most recent call last):
[Fri Feb 07 17:49:55.717475 2020] [wsgi:error] [pid 15212] [remote 192.168.1.22:35666]   File "/home/pi/maison/web_app/site_maison.wsgi", line 2, in <module>
[Fri Feb 07 17:49:55.717522 2020] [wsgi:error] [pid 15212] [remote 192.168.1.22:35666]     with open(activate_this) as file_:
[Fri Feb 07 17:49:55.717678 2020] [wsgi:error] [pid 15212] [remote 192.168.1.22:35666] FileNotFoundError: [Errno 2] No such file or directory: 'test_loop.py'
[Fri Feb 07 17:53:44.272931 2020] [wsgi:error] [pid 15360] [remote 192.168.1.22:35678] mod_wsgi (pid=15360): Target WSGI script '/home/pi/maison/web_app/site_maison.wsgi' cannot be loaded as Python module.
[Fri Feb 07 17:53:44.273291 2020] [wsgi:error] [pid 15360] [remote 192.168.1.22:35678] mod_wsgi (pid=15360): Exception occurred processing WSGI script '/home/pi/maison/web_app/site_maison.wsgi'.
[Fri Feb 07 17:53:44.320512 2020] [wsgi:error] [pid 15360] [remote 192.168.1.22:35678] Traceback (most recent call last):
[Fri Feb 07 17:53:44.320814 2020] [wsgi:error] [pid 15360] [remote 192.168.1.22:35678]   File "/home/pi/maison/web_app/site_maison.wsgi", line 3, in <module>
[Fri Feb 07 17:53:44.320864 2020] [wsgi:error] [pid 15360] [remote 192.168.1.22:35678]     exec(file_.read(), dict(__file__=activate_this))
[Fri Feb 07 17:53:44.320958 2020] [wsgi:error] [pid 15360] [remote 192.168.1.22:35678]   File "<string>", line 2, in <module>
[Fri Feb 07 17:53:44.321118 2020] [wsgi:error] [pid 15360] [remote 192.168.1.22:35678] ImportError: No module named 'Rpi'
[Fri Feb 07 17:55:14.865914 2020] [wsgi:error] [pid 15478] [remote 192.168.1.22:35684] mod_wsgi (pid=15478): Target WSGI script '/home/pi/maison/web_app/site_maison.wsgi' cannot be loaded as Python module.
[Fri Feb 07 17:55:14.866264 2020] [wsgi:error] [pid 15478] [remote 192.168.1.22:35684] mod_wsgi (pid=15478): Exception occurred processing WSGI script '/home/pi/maison/web_app/site_maison.wsgi'.
[Fri Feb 07 17:55:14.910965 2020] [wsgi:error] [pid 15478] [remote 192.168.1.22:35684] Traceback (most recent call last):
[Fri Feb 07 17:55:14.911139 2020] [wsgi:error] [pid 15478] [remote 192.168.1.22:35684]   File "/home/pi/maison/web_app/site_maison.wsgi", line 3, in <module>
[Fri Feb 07 17:55:14.911165 2020] [wsgi:error] [pid 15478] [remote 192.168.1.22:35684]     exec(file_.read(), dict(__file__=activate_this))
[Fri Feb 07 17:55:14.911211 2020] [wsgi:error] [pid 15478] [remote 192.168.1.22:35684]   File "<string>", line 5, in <module>
[Fri Feb 07 17:55:14.911294 2020] [wsgi:error] [pid 15478] [remote 192.168.1.22:35684] NameError: name 'sgndgsgok' is not defined
[Fri Feb 07 17:55:30.275236 2020] [wsgi:error] [pid 15506] /home/pi/maison/web_app/test_loop.py:5: RuntimeWarning: This channel is already in use, continuing anyway.  Use GPIO.setwarnings(False) to disable warnings.
[Fri Feb 07 17:55:30.275447 2020] [wsgi:error] [pid 15506]   GPIO.setup(3, GPIO.OUT, initial = GPIO.HIGH)
[Fri Feb 07 17:55:50.187617 2020] [wsgi:error] [pid 15507] [client 192.168.1.22:35686] Truncated or oversized response headers received from daemon process 'maison': /home/pi/maison/web_app/site_maison.wsgi
[Fri Feb 07 17:55:54.252743 2020] [wsgi:error] [pid 15535] /home/pi/maison/web_app/test_loop.py:5: RuntimeWarning: This channel is already in use, continuing anyway.  Use GPIO.setwarnings(False) to disable warnings.
[Fri Feb 07 17:55:54.252955 2020] [wsgi:error] [pid 15535]   GPIO.setup(3, GPIO.OUT, initial = GPIO.HIGH)
[Fri Feb 07 18:00:54.293980 2020] [wsgi:error] [pid 15538] [client 192.168.1.22:35688] Timeout when reading response headers from daemon process 'maison': /home/pi/maison/web_app/site_maison.wsgi
[Fri Feb 07 18:06:42.034199 2020] [wsgi:error] [pid 16123] /home/pi/maison/web_app/test_loop.py:5: RuntimeWarning: This channel is already in use, continuing anyway.  Use GPIO.setwarnings(False) to disable warnings.
[Fri Feb 07 18:06:42.034377 2020] [wsgi:error] [pid 16123]   GPIO.setup(3, GPIO.OUT, initial = GPIO.HIGH)
